<?xml version="1.0" ?>
<robot name="camel_rmdx8_pro">

  <material name="black">
    <color rgba="0.0 0.0 0.0 1.0"/>
  </material>

  <material name="gray">
    <color rgba="0.5 0.5 0.5 1.0"/>
  </material>

  <material name="Aquamarine">
    <color rgba="0.364 0.733 0.608 1.0"/>
  </material>

  <material name="Aqua">
    <color rgba="0.0 0.733 0.733 1.0"/>
  </material>

  <link name="world"/>
  <joint name="fixed_world" type="fixed">
    <parent link="world"/>
    <child link="base"/>
  </joint>

  <link name="base">
    <visual>
      <origin rpy="0 0 0" xyz="0 0 0.025"/>
      <geometry>
        <cylinder length="0.05" radius="0.05"/>
      </geometry>
      <material name="gray"/>
    </visual>
    <inertial>
      <mass value="0.767"/>
      <inertia ixx="1.0" ixy="0.0" ixz="0.0" iyy="1.0" iyz="0.0" izz="1.0"/>
    </inertial>
  </link>

  <joint name="yaw" type="revolute">
    <origin rpy="0 0 0" xyz="0 0 0.05"/>
    <parent link="base"/>
    <child link="test_link"/>
    <axis xyz="0 0 1"/>
  </joint>

  <link name="test_link">
    <visual>
      <origin rpy="0 0 0" xyz="0.1 0 0.00425"/>
      <geometry>
        <box size="0.2 0.03 0.0085"/>
      </geometry>
      <material name="Aquamarine"/>
    </visual>
    <visual>
          <origin rpy="0 0 0" xyz="0.2 0 0.00425"/>
          <geometry>
            <cylinder length="0.0085" radius="0.021"/>
          </geometry>
          <material name="Aquamarine"/>
        </visual>
  </link>

  
</robot>